<?xml version="1.0"?>
<robot name="one">

  <material name="black">
    <color rgba="0 0 0 0.5"/>
  </material>
  <material name="white">
    <color rgba="1 1 1 0.5"/>
  </material>
  <material name="red">
    <color rgba="1 0 0 0.5"/>
  </material>
  <material name="green">
    <color rgba="0 1 0 0.5"/>
  </material>
  <material name="blue">
    <color rgba="0 0 1 0.5"/>
  </material>
    <material name="cyan">
    <color rgba="0 1 1 0.5"/>
  </material>
  <material name="magenta">
    <color rgba="1 0 1 0.5"/>
  </material>
  <material name="yellow">
    <color rgba="1 1 0 0.5"/>
  </material>

  <link name="base_link">
    <visual>
      <geometry>
        <box size="3.0 1.0 1.0"/>
      </geometry>
      <origin xyz="0 0 0" rpy="0 0 0"/>
      <material name="blue"/>
    </visual>
  </link>

  <link name="neck_link">
    <visual>
      <geometry>
        <box size="1.0 1.0 1.5"/>
      </geometry>
      <origin xyz="0 0 0.75" rpy="0 0 0"/>
      <material name="cyan"/>
    </visual>
  </link>

  <link name="head_link">
    <visual>
      <geometry>
        <box size="0.75 0.75 0.75"/>
      </geometry>
      <origin xyz="0.375 0 0" rpy="0 0 0"/>
      <material name="green"/>
    </visual>
  </link>

  <link name="front_leg_one">
    <visual>
      <geometry>
        <box size="0.4 0.4 2"/>
      </geometry>
      <origin xyz="0 0.2 -1" rpy="0 0 0"/>
      <material name="magenta"/>
    </visual>
  </link>

  <link name="front_leg_two">
    <visual>
      <geometry>
        <box size="0.4 0.4 2"/>
      </geometry>
      <origin xyz="0 -0.2 -1" rpy="0 0 0"/>
      <material name="magenta"/>
    </visual>
  </link>
  
  <link name="back_leg_one">
    <visual>
      <geometry>
        <box size="0.4 0.4 2"/>
      </geometry>
      <origin xyz="0 0.2 -1" rpy="0 0 0"/>
      <material name="magenta"/>
    </visual>
  </link>
  
  <link name="back_leg_two">
    <visual>
      <geometry>
        <box size="0.4 0.4 2"/>
      </geometry>
      <origin xyz="0 -0.2 -1" rpy="0 0 0"/>
      <material name="magenta"/>
    </visual>
  </link>

  <joint name="base_to_neck" type="continuous">
    <parent link="base_link"/>
    <child link="neck_link"/>
    <axis xyz="0 0 1"/>
    <origin xyz="1.0 0 0.5" rpy="0 0 0"/>
  </joint>

  <joint name="neck_to_head" type="fixed">
    <parent link="neck_link"/>
    <child link="head_link"/>
    <origin xyz="0.5 0 1.125" rpy="0 0 0"/>
  </joint>
  
  <joint name="front_joint_one" type="revolute">
    <axis xyz="0 1 0"/>
    <limit effort = "1000.0" lower="1.57" upper="-1.57" velocity="0.5"/>
    <origin xyz="1.0 0.5 0" rpy="0 0 0"/>
    <parent link="base_link"/>
    <child link="front_leg_one"/>
  </joint>
  
  <joint name="front_joint_two" type="revolute">
    <axis xyz="0 1 0"/>
    <limit effort = "1000.0" lower="1.57" upper="-1.57" velocity="0.5"/>
    <origin xyz="1.0 -0.5 0" rpy="0 0 0"/>
    <parent link="base_link"/>
    <child link="front_leg_two"/>
  </joint>
  
  <joint name="back_joint_one" type="revolute">
    <axis xyz="0 1 0"/>
    <limit effort = "1000.0" lower="1.57" upper="-1.57" velocity="0.5"/>
    <origin xyz="-1.0 0.5 0" rpy="0 0 0"/>
    <parent link="base_link"/>
    <child link="back_leg_one"/>
  </joint>
  
  <joint name="back_joint_two" type="revolute">
    <axis xyz="0 1 0"/>
    <limit effort = "1000.0" lower="1.57" upper="-1.57" velocity="0.5"/>
    <origin xyz="-1.0 -0.5 0" rpy="0 0 0"/>
    <parent link="base_link"/>
    <child link="back_leg_two"/>
  </joint>

</robot>
